Workbook
Name EvidenceStatusList: _EvidenceTypeLists!$A$1:$A$11
Name ImpactScore: 'Risk Matrix'!$E$3:$E$7
Name LikelihoodScore: 'Risk Matrix'!$A$3:$A$7
Name MaturityLevel: 'Maturity Scale'!$B$1:$B$5
Name MaturityScore: 'Maturity Scale'!$A$1:$A$5
Name RiskScore: 'Risk Matrix'!$A$11:$A$14

Sheet Evidence Register
A2: Function | B2: Category | C2: Subcategory | D2: Subcategory description | E2: Evidence should fulfill following requirements | F2: Required Evidence | G2: Owner | H2: Evidence Status | I2: Evidence Type(s) | J2: Owner's Remarks | K2: Current Maturity Score | L2: Current Maturity Level | M2: Target Maturity Score | N2: Target Maturity Level | O2: Gap Score | P2: Gap Analysis
A3: GOVERN (GV) | B3: Organizational Context (GV.OC) | C3: GV.OC-01 | D3: The organizational mission is understood and informs cyberSecurity risk management | E3: Ex1: Share the organization's mission (e.g., through vision and mission statements, marketing, and service strategies) to provide a basis for identifying risks that may impede that mission | F3: Mission Statement/Mission Document | G3: CISO | K3: 1 | L3: Partial | M3: 3 | N3: Repeatable | O3: =M3-K3 -> 2 | P3: Mission Statement/Document not provided
A4: GOVERN (GV) | B4: Organizational Context (GV.OC) | C4: GV.OC-02 | D4: Internal and external stakeholders are understood, and their needs and expectations regarding cyberSecurity risk management are understood and considered | E4: Ex1: Identify relevant internal stakeholders and their cyberSecurity-related expectations (e.g., performance and risk expectations of officers, directors, and advisors; cultural expectations of employees) Ex2: Identify relevant external stakeholders and their cyberSecurity-related expectations (e.g., privacy expectations of customers, business expectations of partnerships, compliance expectations of regulators, ethics expectations of society) | F4: Stakeholder Register along with their expectations of internal and external stakeholders | G4: CISO | K4: 2 | L4: Risk Informed | M4: 3 | N4: Repeatable | O4: =M4-K4 -> 1 | P4: Customers and their legal/regulatory requirements are not listed
A5: GOVERN (GV) | B5: Organizational Context (GV.OC) | C5: GV.OC-03 | D5: Legal, regulatory, and contractual requirements regarding cyberSecurity - including privacy and civil liberties obligations - are understood and managed | E5: Ex1: Determine a process to track and manage legal and regulatory requirements regarding protection of individuals' information (e.g., Health Insurance Portability and Accountability Act, California Consumer Privacy Act, General Data Protection Regulation) Ex2: Determine a process to track and manage contractual requirements for cyberSecurity management of supplier, customer, and partner information Ex3: Align the organization's cyberSecurity strategy with legal, regulatory, and contractual requirements | F5: 1. Legal, regulatory and contractual requirements register/matrix covering applicable requirements for India, UAE and Singapore. 2. Process/methodology for identifying, assessing, tracking and updating applicable requirements. 3. Sample evidence showing how significant requirements are communicated and incorporated into cyberSecurity practices. | G5: Legal & Compliance | K5: 1 | L5: Partial | M5: 3 | N5: Repeatable | O5: =M5-K5 -> 2 | P5: Legal, regulatory and contractual requirements of the organization are not listed
A6: GOVERN (GV) | B6: Organizational Context (GV.OC) | C6: GV.OC-04 | D6: Critical objectives, capabilities, and services that external stakeholders depend on or expect from the organization are understood and communicated | E6: Ex1: Establish criteria for determining the criticality of capabilities and services as viewed by internal and external stakeholders Ex2: Determine (e.g., from a business impact analysis) assets and business operations that are vital to achieving mission objectives and the potential impact of a loss (or partial loss) of such operations Ex3: Establish and communicate resilience objectives (e.g., recovery time objectives) for delivering critical capabilities and services in various operating states (e.g., under attack, during recovery, normal operation) | F6: Key Critical Services for external stakeholder: -Policy/Criteria to determine Key Critical Services, -List of critical objectives, capabilities and services, including relevant assets and stakeholder dependencies, with applicable SLA/RTO requirements. -Communication evidence | G6: IT operations | K6: 2 | L6: Risk Informed | M6: 3 | N6: Repeatable | O6: =M6-K6 -> 1 | P6: Centralized inventory of all the critical services and assets should be defined
A7: GOVERN (GV) | B7: Organizational Context (GV.OC) | C7: GV.OC-05 | D7: Outcomes, capabilities, and services that the organization depends on are understood and communicated | E7: Ex1: Create an inventory of the organization's dependencies on external resources (e.g., facilities, cloud-based hosting providers) and their relationships to organizational assets and business functions Ex2: Identify and document external dependencies that are potential points of failure for the organization's critical capabilities and services, and share that information with appropriate personnel | F7: 1. Dependency inventory/mapping showing critical services, business functions and their dependencies on external/internal resources. 2. Identification/classification of critical dependencies and potential points of failure. 3. Relevant SLA/RTO/dependency requirements. 4. Evidence that dependency information is communicated to relevant personnel. | G7: IT operations | K7: 2 | L7: Risk Informed | M7: 3 | N7: Repeatable | O7: =M7-K7 -> 1 | P7: organization is aware about the dependencies but centralized inventory is not maintained
A8: GOVERN (GV) | B8: Risk Management Strategy (GV.RM) | C8: GV.RM-01 | D8: Risk management objectives are established and agreed to by organizational stakeholders | E8: Ex1: Update near-term and long-term cyberSecurity risk management objectives as part of annual strategic planning and when major changes occur Ex2: Establish measurable objectives for cyberSecurity risk management (e.g., manage the quality of user training, ensure adequate risk protection for industrial control systems) Ex3: Senior leaders agree about cyberSecurity objectives and use them for measuring and managing risk and performance | F8: Risk Management Policy defining measurable risk management objectives with evidence of management approval/endorsement | G8: CISO | K8: 3 | L8: =VLOOKUP(K8, 'Maturity Scale'!A:B,2,FALSE) -> Repeatable | M8: 3 | N8: =VLOOKUP(M8,'Maturity Scale'!A:B,2,FALSE) -> Repeatable | O8: =M8-K8 -> 0 | P8: Risk Management objectives are defined in the Risk Management policy
A9: GOVERN (GV) | B9: Risk Management Strategy (GV.RM) | C9: GV.RM-02 | D9: Risk appetite and risk tolerance statements are established, communicated, and maintained | E9: Ex1: Determine and communicate risk appetite statements that convey expectations about the appropriate level of risk for the organization Ex2: Translate risk appetite statements into specific, measurable, and broadly understandable risk tolerance statements Ex3: Refine organizational objectives and risk appetite periodically based on known risk exposure and residual risk | F9: 1. Risk Management Policy defining risk tolerance and risk appetite statements 2. Evidence of Communication 3. Evidence of periodic review/versions | G9: CISO | K9: 2 | L9: =VLOOKUP(K9, 'Maturity Scale'!A:B,2,FALSE) -> Risk Informed | M9: 3 | N9: =VLOOKUP(M9,'Maturity Scale'!A:B,2,FALSE) -> Repeatable | O9: =M9-K9 -> 1 | P9: Risk Apetitie is defined in Risk Management Policy but Risk Tolerence is not consistently docuemented
A10: GOVERN (GV) | B10: Risk Management Strategy (GV.RM) | C10: GV.RM-03 | D10: CyberSecurity risk management activities and outcomes are included in enterprise risk management processes | E10: Ex1: Aggregate and manage cyberSecurity risks alongside other enterprise risks (e.g., compliance, financial, operational, regulatory, reputational, safety) Ex2: Include cyberSecurity risk managers in enterprise risk management planning Ex3: Establish criteria for escalating cyberSecurity risks within enterprise risk management | F10: 1. Policy showing integration of cberSecurity risk management with enterprise risk management. 2.Inclusion of cyber risk in enterprise risk Register 3. Escalation matrix leading cyber risk to enterprise channel | G10: CISO | K10: 3 | L10: =VLOOKUP(K10, 'Maturity Scale'!A:B,2,FALSE) -> Repeatable | M10: 3 | N10: =VLOOKUP(M10,'Maturity Scale'!A:B,2,FALSE) -> Repeatable | O10: =M10-K10 -> 0 | P10: Enterprise risk register consist of cyber security risk
A11: GOVERN (GV) | B11: Risk Management Strategy (GV.RM) | C11: GV.RM-04 | D11: Strategic direction that describes appropriate risk response options is established and communicated | E11: Ex1: Specify criteria for accepting and avoiding cyberSecurity risk for various classifications of data Ex2: Determine whether to purchase cyberSecurity insurance Ex3: Document conditions under which shared responsibility models are acceptable (e.g., outsourcing certain cyberSecurity functions, having a third party perform financial transactions on behalf of the organization, using public cloud-based services) | F11: Risk Management Policy showing risk response criteria + communication | G11: CISO | K11: 3 | L11: =VLOOKUP(K11, 'Maturity Scale'!A:B,2,FALSE) -> Repeatable | M11: 3 | N11: =VLOOKUP(M11,'Maturity Scale'!A:B,2,FALSE) -> Repeatable | O11: =M11-K11 -> 0 | P11: Risk response options are mentioned in Risk Management policy
A12: GOVERN (GV) | B12: Risk Management Strategy (GV.RM) | C12: GV.RM-05 | D12: Lines of communication across the organization are established for cyberSecurity risks, including risks from suppliers and other third parties | E12: Ex1: Determine how to update senior executives, directors, and management on the organization's cyberSecurity posture at agreed-upon intervals Ex2: Identify how all departments across the organization - such as management, operations, internal auditors, legal, acquisition, physical Security, and HR - will communicate with each other about cyberSecurity risks | F12: Template/Policy depicting communication channel among different department of the organization and with Third parties Sample of cyber Security risk reporting between departments/third parties | G12: CISO | K12: 1 | L12: =VLOOKUP(K12, 'Maturity Scale'!A:B,2,FALSE) -> Partial | M12: 3 | N12: =VLOOKUP(M12,'Maturity Scale'!A:B,2,FALSE) -> Repeatable | O12: =M12-K12 -> 2 | P12: No clear evidence regarding established lines of communication
A13: GOVERN (GV) | B13: Risk Management Strategy (GV.RM) | C13: GV.RM-06 | D13: A standardized method for calculating, documenting, categorizing, and prioritizing cyberSecurity risks is established and communicated | E13: Ex1: Establish criteria for using a quantitative approach to cyberSecurity risk analysis, and specify probability and exposure formulas Ex2: Create and use templates (e.g., a risk register) to document cyberSecurity risk information (e.g., risk description, exposure, treatment, and ownership) Ex3: Establish criteria for risk prioritization at the appropriate levels within the enterprise Ex4: Use a consistent list of risk categories to support integrating, aggregating, and comparing cyberSecurity risks | F13: 1. Risk Management Policy defing Risk Matrix/Risk Classification Criteria 2. Evidence of communication 3. Sample to depict actual implementation as per policy/criteria | G13: CISO | K13: 2 | L13: =VLOOKUP(K13, 'Maturity Scale'!A:B,2,FALSE) -> Risk Informed | M13: 3 | N13: =VLOOKUP(M13,'Maturity Scale'!A:B,2,FALSE) -> Repeatable | O13: =M13-K13 -> 1 | P13: Policy metioned risk is generally calculated on likelihood and impact; no clear evidence of formal documentation of the process
A14: GOVERN (GV) | B14: Risk Management Strategy (GV.RM) | C14: GV.RM-07 | D14: Strategic opportunities (i.e., positive risks) are characterized and are included in organizational cyberSecurity risk discussions | E14: Ex1: Define and communicate guidance and methods for identifying opportunities and including them in risk discussions (e.g., strengths, weaknesses, opportunities, and threats [SWOT] analysis) Ex2: Identify stretch goals and document them Ex3: Calculate, document, and prioritize positive risks alongside negative risks | F14: Risk Management Policy depicting process to deal with identified opportunities to improve. Evidence showing mechanism to deal with opportunities. | G14: CISO | K14: 1 | L14: =VLOOKUP(K14, 'Maturity Scale'!A:B,2,FALSE) -> Partial | M14: 3 | N14: =VLOOKUP(M14,'Maturity Scale'!A:B,2,FALSE) -> Repeatable | O14: =M14-K14 -> 2 | P14: No mention of how organization handles positive risks
A15: GOVERN (GV) | B15: Roles, Responsibilities, and Authorities (GV.RR) | C15: GV.RR-01 | D15: Organizational leadership is responsible and accountable for cyberSecurity risk and fosters a culture that is risk-aware, ethical, and continually improving | E15: Ex1: Leaders (e.g., directors) agree on their roles and responsibilities in developing, implementing, and assessing the organization's cyberSecurity strategy Ex2: Share leaders' expectations regarding a secure and ethical culture, especially when current events present the opportunity to highlight positive or negative examples of cyberSecurity risk management Ex3: Leaders direct the CISO to maintain a comprehensive cyberSecurity risk strategy and review and update it at least annually and after major events Ex4: Conduct reviews to ensure adequate authority and coordination among those responsible for managing cyberSecurity risk | F15: Evidences showing leadership endorsement Sample of leadership endorsement Roles & Responsibilities should be defined in Information Security Policy | G15: CISO | K15: 3 | L15: =VLOOKUP(K15, 'Maturity Scale'!A:B,2,FALSE) -> Repeatable | M15: 3 | N15: =VLOOKUP(M15,'Maturity Scale'!A:B,2,FALSE) -> Repeatable | O15: =M15-K15 -> 0 | P15: Periodic reviews are done and risk posture is presented to CIO by CISO
A16: GOVERN (GV) | B16: Roles, Responsibilities, and Authorities (GV.RR) | C16: GV.RR-02 | D16: Roles, responsibilities, and authorities related to cyberSecurity risk management are established, communicated, understood, and enforced | E16: Ex1: Document risk management roles and responsibilities in policy Ex2: Document who is responsible and accountable for cyberSecurity risk management activities and how those teams and individuals are to be consulted and informed Ex3: Include cyberSecurity responsibilities and performance requirements in personnel descriptions Ex4: Document performance goals for personnel with cyberSecurity risk management responsibilities, and periodically measure performance to identify areas for improvement Ex5: Clearly articulate cyberSecurity responsibilities within operations, risk functions, and internal audit functions | F16: 1. Information Security policy where cyberSecurity roles and responsibilities are defined 2. Evidence of communication | G16: CISO | K16: 3 | L16: =VLOOKUP(K16, 'Maturity Scale'!A:B,2,FALSE) -> Repeatable | M16: 3 | N16: =VLOOKUP(M16,'Maturity Scale'!A:B,2,FALSE) -> Repeatable | O16: =M16-K16 -> 0 | P16: Risk owners and other responsibilities are defined and communicated
A17: GOVERN (GV) | B17: Roles, Responsibilities, and Authorities (GV.RR) | C17: GV.RR-03 | D17: Adequate resources are allocated commensurate with the cyberSecurity risk strategy, roles, responsibilities, and policies | E17: Ex1: Conduct periodic management reviews to ensure that those given cyberSecurity risk management responsibilities have the necessary authority Ex2: Identify resource allocation and investment in line with risk tolerance and response Ex3: Provide adequate and sufficient people, process, and technical resources to support the cyberSecurity strategy | F17: 1. CyberSecurity resource/budget plan or equivalent resource allocation evidence. 2. CyberSecurity staffing/resource allocation information. 3. Evidence of management review/approval of cyberSecurity resource requirements, where applicable. | G17: CISO | K17: 1 | L17: =VLOOKUP(K17, 'Maturity Scale'!A:B,2,FALSE) -> Partial | M17: 3 | N17: =VLOOKUP(M17,'Maturity Scale'!A:B,2,FALSE) -> Repeatable | O17: =M17-K17 -> 2 | P17: No evidence on how organization does ensure the resource alllocation
A18: GOVERN (GV) | B18: Roles, Responsibilities, and Authorities (GV.RR) | C18: GV.RR-04 | D18: CyberSecurity is included in human resources practices | E18: Ex1: Integrate cyberSecurity risk management considerations into human resources processes (e.g., personnel screening, onboarding, change notification, offboarding) Ex2: Consider cyberSecurity knowledge to be a positive factor in hiring, training, and retention decisions Ex3: Conduct background checks prior to onboarding new personnel for sensitive roles, and periodically repeat background checks for personnel with such roles Ex4: Define and enforce obligations for personnel to be aware of, adhere to, and uphold Security policies as they relate to their roles | F18: HR- onboarding/offboarding and other policies depicting inclusion of cyberSecurity in practices Monitoring process and evidence | G18: HR | K18: 1 | L18: =VLOOKUP(K18, 'Maturity Scale'!A:B,2,FALSE) -> Partial | M18: 3 | N18: =VLOOKUP(M18,'Maturity Scale'!A:B,2,FALSE) -> Repeatable | O18: =M18-K18 -> 2 | P18: Onboarding policy should define the cybersecurity rquirements like mandatory trainings and a process to monitor the training record should be established
A19: GOVERN (GV) | B19: Policy (GV.PO) | C19: GV.PO-01 | D19: Policy for managing cyberSecurity risks is established based on organizational context, cyberSecurity strategy, and priorities and is communicated and enforced | E19: Ex1: Create, disseminate, and maintain an understandable, usable risk management policy with statements of management intent, expectations, and direction Ex2: Periodically review policy and supporting processes and procedures to ensure that they align with risk management strategy objectives and priorities, as well as the high-level direction of the cyberSecurity policy Ex3: Require approval from senior management on policy Ex4: Communicate cyberSecurity risk management policy and supporting processes and procedures across the organization Ex5: Require personnel to acknowledge receipt of policy when first hired, annually, and whenever policy is updated | F19: 1. Risk Management Policy 2. Evidence of communication and approval | G19: CISO | K19: 3 | L19: =VLOOKUP(K19, 'Maturity Scale'!A:B,2,FALSE) -> Repeatable | M19: 3 | N19: =VLOOKUP(M19,'Maturity Scale'!A:B,2,FALSE) -> Repeatable | O19: =M19-K19 -> 0 | P19: Risk Management policy is well established
A20: GOVERN (GV) | B20: Policy (GV.PO) | C20: GV.PO-02 | D20: Policy for managing cyberSecurity risks is reviewed, updated, communicated, and enforced to reflect changes in requirements, threats, technology, and organizational mission | E20: Ex1: Update policy based on periodic reviews of cyberSecurity risk management results to ensure that policy and supporting processes and procedures adequately maintain risk at an acceptable level Ex2: Provide a timeline for reviewing changes to the organization's risk environment (e.g., changes in risk or in the organization's mission objectives), and communicate recommended policy updates Ex3: Update policy to reflect changes in legal and regulatory requirements Ex4: Update policy to reflect changes in technology (e.g., adoption of artificial intelligence) and changes to the business (e.g., acquisition of a new business, new contract requirements) | F20: Risk Management policy versions and process to manage change/update in policy | G20: CISO | K20: 2 | L20: =VLOOKUP(K20, 'Maturity Scale'!A:B,2,FALSE) -> Risk Informed | M20: 3 | N20: =VLOOKUP(M20,'Maturity Scale'!A:B,2,FALSE) -> Repeatable | O20: =M20-K20 -> 1 | P20: Policy is established but no process to manage change/update the policy defined
A21: GOVERN (GV) | B21: Oversight (GV.OV) | C21: GV.OV-01 | D21: CyberSecurity risk management strategy outcomes are reviewed to inform and adjust strategy and direction | E21: Ex1: Measure how well the risk management strategy and risk results have helped leaders make decisions and achieve organizational objectives Ex2: Examine whether cyberSecurity risk strategies that impede operations or innovation should be adjusted | F21: 1. Records/minutes/reports of periodic cyberSecurity risk management strategy reviews. 2. Evidence of management/leadership review of cyberSecurity risk posture and strategy. 3. Resulting decisions, actions or strategy updates, where applicable. | G21: CISO | K21: TBD | L21: =VLOOKUP(K21, 'Maturity Scale'!A:B,2,FALSE) -> TBD | M21: TBD | N21: =VLOOKUP(M21,'Maturity Scale'!A:B,2,FALSE) -> TBD | O21: =M21-K21 -> #VALUE!
A22: GOVERN (GV) | B22: Oversight (GV.OV) | C22: GV.OV-02 | D22: The cyberSecurity risk management strategy is reviewed and adjusted to ensure coverage of organizational requirements and risks | E22: Ex1: Review audit findings to confirm whether the existing cyberSecurity strategy has ensured compliance with internal and external requirements Ex2: Review the performance oversight of those in cyberSecurity-related roles to determine whether policy changes are necessary Ex3: Review strategy in light of cyberSecurity incidents | F22: 1. Reports/results of periodic reviews, audits or assessments evaluating whether the cyberSecurity risk management strategy addresses organizational requirements and risks. 2. Evidence of actions or changes to the cyberSecurity risk management strategy resulting from identified findings, where applicable. | G22: CISO | K22: TBD | L22: =VLOOKUP(K22, 'Maturity Scale'!A:B,2,FALSE) -> TBD | M22: TBD | N22: =VLOOKUP(M22,'Maturity Scale'!A:B,2,FALSE) -> TBD | O22: =M22-K22 -> #VALUE!
A23: GOVERN (GV) | B23: Oversight (GV.OV) | C23: GV.OV-03 | D23: Organizational cyberSecurity risk management performance is evaluated and reviewed for adjustments needed | E23: Ex1: Review key performance indicators (KPIs) to ensure that organization-wide policies and procedures achieve objectives Ex2: Review key risk indicators (KRIs) to identify risks the organization faces, including likelihood and potential impact Ex3: Collect and communicate metrics on cyberSecurity risk management with senior leadership | F23: 1. CyberSecurity risk management performance metrics/KPIs or equivalent measures. 2. Periodic performance review records showing comparison of results over time. 3. Evidence of corrective/improvement actions resulting from performance reviews, where applicable. | G23: CISO | K23: 2 | L23: =VLOOKUP(K23, 'Maturity Scale'!A:B,2,FALSE) -> Risk Informed | M23: 3 | N23: =VLOOKUP(M23,'Maturity Scale'!A:B,2,FALSE) -> Repeatable | O23: =M23-K23 -> 1 | P23: Periodic riskds reviews are done, but no clear evidenvce on comprehensive review of risk management process
A24: GOVERN (GV) | B24: CyberSecurity Supply Chain Risk Management (GV.SC) | C24: GV.SC-01 | D24: A cyberSecurity supply chain risk management program, strategy, objectives, policies, and processes are established and agreed to by organizational stakeholders | E24: Ex1: Establish a strategy that expresses the objectives of the cyberSecurity supply chain risk management program Ex2: Develop the cyberSecurity supply chain risk management program, including a plan (with milestones), policies, and procedures that guide implementation and improvement of the program, and share the policies and procedures with the organizational stakeholders Ex3: Develop and implement program processes based on the strategy, objectives, policies, and procedures that are agreed upon and performed by the organizational stakeholders Ex4: Establish a cross-organizational mechanism that ensures alignment between functions that contribute to cyberSecurity supply chain risk management, such as cyberSecurity, IT, operations, legal, human resources, and engineering | F24: Supply Chain Risk Management Policy/TPRM policy | G24: CISO | K24: 1 | L24: =VLOOKUP(K24, 'Maturity Scale'!A:B,2,FALSE) -> Partial | M24: 3 | N24: =VLOOKUP(M24,'Maturity Scale'!A:B,2,FALSE) -> Repeatable | O24: =M24-K24 -> 2 | P24: No supply chain or TPRM policy in place
A25: GOVERN (GV) | B25: CyberSecurity Supply Chain Risk Management (GV.SC) | C25: GV.SC-02 | D25: CyberSecurity roles and responsibilities for suppliers, customers, and partners are established, communicated, and coordinated internally and externally | E25: Ex1: Identify one or more specific roles or positions that will be responsible and accountable for planning, resourcing, and executing cyberSecurity supply chain risk management activities Ex2: Document cyberSecurity supply chain risk management roles and responsibilities in policy Ex3: Create responsibility matrixes to document who will be responsible and accountable for cyberSecurity supply chain risk management activities and how those teams and individuals will be consulted and informed Ex4: Include cyberSecurity supply chain risk management responsibilities and performance requirements in personnel descriptions to ensure clarity and improve accountability Ex5: Document performance goals for personnel with cyberSecurity risk management-specific responsibilities, and periodically measure them to demonstrate and improve performance Ex6: Develop roles and responsibilities for suppliers, customers, and business partners to address shared responsibilities for applicable cyberSecurity risks, and integrate them into organizational policies and applicable third-party agreements Ex7: Internally communicate cyberSecurity supply chain risk management roles and responsibilities for third parties Ex8: Establish rules and protocols for information sharing and reporting processes between the organization and its suppliers | F25: Supply Chain Risk Management Policy/TPRM policy depicting the roles and responsibilities for Suppliers, Customers & Partners | G25: CISO | K25: 1 | L25: =VLOOKUP(K25, 'Maturity Scale'!A:B,2,FALSE) -> Partial | M25: 3 | N25: =VLOOKUP(M25,'Maturity Scale'!A:B,2,FALSE) -> Repeatable | O25: =M25-K25 -> 2 | P25: No supply chain or TPRM policy in place
A26: GOVERN (GV) | B26: CyberSecurity Supply Chain Risk Management (GV.SC) | C26: GV.SC-03 | D26: CyberSecurity supply chain risk management is integrated into cyberSecurity and enterprise risk management, risk assessment, and improvement processes | E26: Ex1: Identify areas of alignment and overlap with cyberSecurity and enterprise risk management Ex2: Establish integrated control sets for cyberSecurity risk management and cyberSecurity supply chain risk management Ex3: Integrate cyberSecurity supply chain risk management into improvement processes Ex4: Escalate material cyberSecurity risks in supply chains to senior management, and address them at the enterprise risk management level | F26: CyberSecurity and enterprise risk register contains risk related to supply chain | G26: CISO | K26: 1 | L26: =VLOOKUP(K26, 'Maturity Scale'!A:B,2,FALSE) -> Partial | M26: 3 | N26: =VLOOKUP(M26,'Maturity Scale'!A:B,2,FALSE) -> Repeatable | O26: =M26-K26 -> 2 | P26: No supply chain or TPRM policy in place
A27: GOVERN (GV) | B27: CyberSecurity Supply Chain Risk Management (GV.SC) | C27: GV.SC-04 | D27: Suppliers are known and prioritized by criticality | E27: Ex1: Develop criteria for supplier criticality based on, for example, the sensitivity of data processed or possessed by suppliers, the degree of access to the organization's systems, and the importance of the products or services to the organization's mission Ex2: Keep a record of all suppliers, and prioritize suppliers based on the criticality criteria | F27: 1. Supplier classification policy/criteria 2. Supplier List by Criticality | G27: Procurement | K27: 3 | L27: =VLOOKUP(K27, 'Maturity Scale'!A:B,2,FALSE) -> Repeatable | M27: 3 | N27: =VLOOKUP(M27,'Maturity Scale'!A:B,2,FALSE) -> Repeatable | O27: =M27-K27 -> 0 | P27: Critical suppliers are identified for additional security checks
A28: GOVERN (GV) | B28: CyberSecurity Supply Chain Risk Management (GV.SC) | C28: GV.SC-05 | D28: Requirements to address cyberSecurity risks in supply chains are established, prioritized, and integrated into contracts and other types of agreements with suppliers and other relevant third parties | E28: Ex1: Establish Security requirements for suppliers, products, and services commensurate with their criticality level and potential impact if compromised Ex2: Include all cyberSecurity and supply chain requirements that third parties must follow and how compliance with the requirements may be verified in default contractual language Ex3: Define the rules and protocols for information sharing between the organization and its suppliers and sub-tier suppliers in agreements Ex4: Manage risk by including Security requirements in agreements based on their criticality and potential impact if compromised Ex5: Define Security requirements in service-level agreements (SLAs) for monitoring suppliers for acceptable Security performance throughout the supplier relationship lifecycle Ex6: Contractually require suppliers to disclose cyberSecurity features, functions, and vulnerabilities of their products and services for the life of the product or the term of service Ex7: Contractually require suppliers to provide and maintain a current component inventory (e.g., software or hardware bill of materials) for critical products Ex8: Contractually require suppliers to vet their employees and guard against insider threats Ex9: Contractually require suppliers to provide evidence of performing acceptable Security practices through, for example, self-attestation, conformance to known standards, certifications, or inspections Ex10: Specify in contracts and other agreements the rights and responsibilities of the organization, its suppliers, and their supply chains, with respect to potential cyberSecurity risks | F28: 1. Due diligence questionnaire 2. Evidence of contracts/agreements showing the integration of cyberSecurity risk. | G28: Procurement | K28: 2 | L28: =VLOOKUP(K28, 'Maturity Scale'!A:B,2,FALSE) -> Risk Informed | M28: 3 | N28: =VLOOKUP(M28,'Maturity Scale'!A:B,2,FALSE) -> Repeatable | O28: =M28-K28 -> 1 | P28: Cyber security risks are included in contratc but only for high risk tech suppliers
A29: GOVERN (GV) | B29: CyberSecurity Supply Chain Risk Management (GV.SC) | C29: GV.SC-06 | D29: Planning and due diligence are performed to reduce risks before entering into formal supplier or other third-party relationships | E29: Ex1: Perform thorough due diligence on prospective suppliers that is consistent with procurement planning and commensurate with the level of risk, criticality, and complexity of each supplier relationship Ex2: Assess the suitability of the technology and cyberSecurity capabilities and the risk management practices of prospective suppliers Ex3: Conduct supplier risk assessments against business and applicable cyberSecurity requirements Ex4: Assess the authenticity, integrity, and Security of critical products prior to acquisition and use | F29: 1. Due diligence questionnaire 2. Evidence of due diligence process | G29: Procurement | K29: 3 | L29: =VLOOKUP(K29, 'Maturity Scale'!A:B,2,FALSE) -> Repeatable | M29: 3 | N29: =VLOOKUP(M29,'Maturity Scale'!A:B,2,FALSE) -> Repeatable | O29: =M29-K29 -> 0 | P29: Procurement performs the due diligence
A30: GOVERN (GV) | B30: CyberSecurity Supply Chain Risk Management (GV.SC) | C30: GV.SC-07 | D30: The risks posed by a supplier, their products and services, and other third parties are understood, recorded, prioritized, assessed, responded to, and monitored over the course of the relationship | E30: Ex1: Adjust assessment formats and frequencies based on the third party's reputation and the criticality of the products or services they provide Ex2: Evaluate third parties' evidence of compliance with contractual cyberSecurity requirements, such as self-attestations, warranties, certifications, and other artifacts Ex3: Monitor critical suppliers to ensure that they are fulfilling their Security obligations throughout the supplier relationship lifecycle using a variety of methods and techniques, such as inspections, audits, tests, or other forms of evaluation Ex4: Monitor critical suppliers, services, and products for changes to their risk profiles, and reevaluate supplier criticality and risk impact accordingly Ex5: Plan for unexpected supplier and supply chain-related interruptions to ensure business continuity | F30: TPRM Policy Supplier assessments results and actions | G30: Procurement | K30: 2 | L30: =VLOOKUP(K30, 'Maturity Scale'!A:B,2,FALSE) -> Risk Informed | M30: 3 | N30: =VLOOKUP(M30,'Maturity Scale'!A:B,2,FALSE) -> Repeatable | O30: =M30-K30 -> 1 | P30: Due diligence is done during onboarding. However, continuous monitoring and risk reporting is missing
A31: GOVERN (GV) | B31: CyberSecurity Supply Chain Risk Management (GV.SC) | C31: GV.SC-08 | D31: Relevant suppliers and other third parties are included in incident planning, response, and recovery activities | E31: Ex1: Define and use rules and protocols for reporting incident response and recovery activities and the status between the organization and its suppliers Ex2: Identify and document the roles and responsibilities of the organization and its suppliers for incident response Ex3: Include critical suppliers in incident response exercises and simulations Ex4: Define and coordinate crisis communication methods and protocols between the organization and its critical suppliers Ex5: Conduct collaborative lessons learned sessions with critical suppliers | F31: Incident response/recovery plan/execution depicting the inclusion of relevant third parties | G31: Security | K31: 3 | L31: =VLOOKUP(K31, 'Maturity Scale'!A:B,2,FALSE) -> Repeatable | M31: 3 | N31: =VLOOKUP(M31,'Maturity Scale'!A:B,2,FALSE) -> Repeatable | O31: =M31-K31 -> 0 | P31: Incident notification and cooperation requirments mentioned
A32: GOVERN (GV) | B32: CyberSecurity Supply Chain Risk Management (GV.SC) | C32: GV.SC-09 | D32: Supply chain Security practices are integrated into cyberSecurity and enterprise risk management programs, and their performance is monitored throughout the technology product and service life cycle | E32: Ex1: Policies and procedures require provenance records for all acquired technology products and services Ex2: Periodically provide risk reporting to leaders about how acquired components are proven to be untampered and authentic Ex3: Communicate regularly among cyberSecurity risk managers and operations personnel about the need to acquire software patches, updates, and upgrades only from authenticated and trustworthy software providers Ex4: Review policies to ensure that they require approved supplier personnel to perform maintenance on supplier products Ex5: Policies and procedure require checking upgrades to critical hardware for unauthorized changes | F32: 1. Evidence showing supply-chain risk management performance is monitored throughout the technology/product/service lifecycle. 2. Supplier performance/Security review records. 3. Evidence of periodic review and improvement of supply-chain risk management activities. 4. Where applicable, evidence of supply-chain risk integration with enterprise risk management. | G32: Procurement | K32: 1 | L32: =VLOOKUP(K32, 'Maturity Scale'!A:B,2,FALSE) -> Partial | M32: 3 | N32: =VLOOKUP(M32,'Maturity Scale'!A:B,2,FALSE) -> Repeatable | O32: =M32-K32 -> 2 | P32: No supply chain or TPRM policy in place
A33: GOVERN (GV) | B33: CyberSecurity Supply Chain Risk Management (GV.SC) | C33: GV.SC-10 | D33: CyberSecurity supply chain risk management plans include provisions for activities that occur after the conclusion of a partnership or service agreement | E33: Ex1: Establish processes for terminating critical relationships under both normal and adverse circumstances Ex2: Define and implement plans for component end-of-life maintenance support and obsolescence Ex3: Verify that supplier access to organization resources is deactivated promptly when it is no longer needed Ex4: Verify that assets containing the organization's data are returned or properly disposed of in a timely, controlled, and safe manner Ex5: Develop and execute a plan for terminating or transitioning supplier relationships that takes supply chain Security risk and resiliency into account Ex6: Mitigate risks to data and systems created by supplier termination Ex7: Manage data leakage risks associated with supplier termination | F33: Supplyy chain risk management policy depicting the plan, criteria to terminate a contract and activities/roles-responsibilities done during or after the termination on contract. | G33: Procurement | K33: 2 | L33: =VLOOKUP(K33, 'Maturity Scale'!A:B,2,FALSE) -> Risk Informed | M33: 3 | N33: =VLOOKUP(M33,'Maturity Scale'!A:B,2,FALSE) -> Repeatable | O33: =M33-K33 -> 1 | P33: Termination procedure exist but no formal policy
A34: IDENTIFY (ID) | B34: Asset Management (ID.AM) | C34: ID.AM-01 | D34: Inventories of hardware managed by the organization are maintained | E34: Ex1: Maintain inventories for all types of hardware, including IT, IoT, OT, and mobile devices Ex2: Constantly monitor networks to detect new hardware and automatically update inventories | F34: 1. Asset register with the list of all hadwares in the organization. 2. Evidence of asset register update | G34: IT operations | K34: 2 | L34: =VLOOKUP(K34, 'Maturity Scale'!A:B,2,FALSE) -> Risk Informed | M34: 3 | N34: =VLOOKUP(M34,'Maturity Scale'!A:B,2,FALSE) -> Repeatable | O34: =M34-K34 -> 1 | P34: IT team manintains the inventory of laptops and servers only.
... A57: PROTECT (PR) | B57: Identity Management, Authentication, and Access Control (PR.AA) | C57: PR.AA-03 | D57: Users, services, and hardware are authenticated | E57: Ex1: Require multifactor authentication Ex2: Enforce policies for the minimum strength of passwords, PINs, and similar authenticators Ex3: Periodically reauthenticate users, services, and hardware based on risk (e.g., in zero trust architectures) Ex4: Ensure that authorized personnel can access accounts essential for protecting safety under emergency conditions | F57: Evidences for authentication mechanism | G57: IT operations | K57: 3 | L57: =VLOOKUP(K57, 'Maturity Scale'!A:B,2,FALSE) -> Repeatable | M57: 3 | N57: =VLOOKUP(M57,'Maturity Scale'!A:B,2,FALSE) -> Repeatable | O57: =M57-K57 -> 0 | P57: Authentication is managed by Identity plateform
A58: PROTECT (PR) | B58: Identity Management, Authentication, and Access Control (PR.AA) | C58: PR.AA-04 | D58: Identity assertions are protected, conveyed, and verified | E58: Ex1: Protect identity assertions that are used to convey authentication and user information through single sign-on systems Ex2: Protect identity assertions that are used to convey authentication and user information between federated systems Ex3: Implement standards-based approaches for identity assertions in all contexts, and follow all guidance for the generation (e.g., data models, metadata), protection (e.g., digital signing, encryption), and verification (e.g., signature validation) of identity assertions | F58: 1. Process/configuration for managing and validating identity assertions used for access decisions. 2. Relevant IAM/federation/authentication configuration or architecture evidence. 3. Representative evidence demonstrating verification of identity information before granting access, where applicable. | G58: IT operations | K58: TBD | L58: =VLOOKUP(K58, 'Maturity Scale'!A:B,2,FALSE) -> TBD | N58: =VLOOKUP(M58,'Maturity Scale'!A:B,2,FALSE) -> #N/A | O58: =M58-K58 -> #VALUE!
A59: PROTECT (PR) | B59: Identity Management, Authentication, and Access Control (PR.AA) | C59: PR.AA-05 | D59: Access permissions, entitlements, and authorizations are defined in a policy, managed, enforced, and reviewed, and incorporate the principles of least privilege and separation of duties | E59: Ex1: Review logical and physical access privileges periodically and whenever someone changes roles or leaves the organization, and promptly rescind privileges that are no longer needed Ex2: Take attributes of the requester and the requested resource into account for authorization decisions (e.g., geolocation, day/time, requester endpoint's cyber health) Ex3: Restrict access and privileges to the minimum necessary (e.g., zero trust architecture) Ex4: Periodically review the privileges associated with critical business functions to confirm proper separation of duties | F59: Access Management Policy depicting the use of principle of least privileges and separation of duties Evidence of periodic access review | G59: IT operations | K59: 1 | L59: =VLOOKUP(K59, 'Maturity Scale'!A:B,2,FALSE) -> Partial | M59: 3 | N59: =VLOOKUP(M59,'Maturity Scale'!A:B,2,FALSE) -> Repeatable | O59: =M59-K59 -> 2 | P59: No formal access management policy
A60: PROTECT (PR) | B60: Identity Management, Authentication, and Access Control (PR.AA) | C60: PR.AA-06 | D60: Physical access to assets is managed, monitored, and enforced commensurate with risk | E60: Ex1: Use Security guards, Security cameras, locked entrances, alarm systems, and other physical controls to monitor facilities and restrict access Ex2: Employ additional physical Security controls for areas that contain high-risk assets Ex3: Escort guests, vendors, and other third parties within areas that contain business-critical assets | F60: Physical Security/access control policy and representative evidence of physical access controls and monitoring, where applicable. | G60: CISO | K60: 1 | L60: =VLOOKUP(K60, 'Maturity Scale'!A:B,2,FALSE) -> Partial | M60: 3 | N60: =VLOOKUP(M60,'Maturity Scale'!A:B,2,FALSE) -> Repeatable | O60: =M60-K60 -> 2 | P60: No evidence on physicall access management
A61: PROTECT (PR) | B61: Awareness and Training (PR.AT) | C61: PR.AT-01 | D61: Personnel are provided with awareness and training so that they possess the knowledge and skills to perform general tasks with cyberSecurity risks in mind | E61: Ex1: Provide basic cyberSecurity awareness and training to employees, contractors, partners, suppliers, and all other users of the organization's non-public resources Ex2: Train personnel to recognize social engineering attempts and other common attacks, report attacks and suspicious activity, comply with acceptable use policies, and perform basic cyber hygiene tasks (e.g., patching software, choosing passwords, protecting credentials) Ex3: Explain the consequences of cyberSecurity policy violations, both to individual users and the organization as a whole Ex4: Periodically assess or test users on their understanding of basic cyberSecurity practices Ex5: Require annual refreshers to reinforce existing practices and introduce new practices | F61: Awareness & Training Policy, Inclusion of awareness & training in KPIs | G61: HR | K61: 1 | L61: =VLOOKUP(K61, 'Maturity Scale'!A:B,2,FALSE) -> Partial | M61: 3 | N61: =VLOOKUP(M61,'Maturity Scale'!A:B,2,FALSE) -> Repeatable | O61: =M61-K61 -> 2 | P61: No training and awareness policy
A62: PROTECT (PR) | B62: Awareness and Training (PR.AT) | C62: PR.AT-02 | D62: Individuals in specialized roles are provided with awareness and training so that they possess the knowledge and skills to perform relevant tasks with cyberSecurity risks in mind | E62: Ex1: Identify the specialized roles within the organization that require additional cyberSecurity training, such as physical and cyberSecurity personnel, finance personnel, senior leadership, and anyone with access to business-critical data Ex2: Provide role-based cyberSecurity awareness and training to all those in specialized roles, including contractors, partners, suppliers, and other third parties Ex3: Periodically assess or test users on their understanding of cyberSecurity practices for their specialized roles Ex4: Require annual refreshers to reinforce existing practices and introduce new practices | F62: Awareness & Training Policy, Inclusion of role specific awareness & training in KPIs Sample role specific KPIs | G62: HR | K62: 1 | L62: =VLOOKUP(K62, 'Maturity Scale'!A:B,2,FALSE) -> Partial | M62: 3 | N62: =VLOOKUP(M62,'Maturity Scale'!A:B,2,FALSE) -> Repeatable | O62: =M62-K62 -> 2 | P62: No training and awareness policy
A63: PROTECT (PR) | B63: Data Security (PR.DS) | C63: PR.DS-01 | D63: The confidentiality, integrity, and availability of data-at-rest are protected | E63: Ex1: Use encryption, digital signatures, and cryptographic hashes to protect the confidentiality and integrity of stored data in files, databases, virtual machine disk images, container images, and other resources Ex2: Use full disk encryption to protect data stored on user endpoints Ex3: Confirm the integrity of software by validating signatures Ex4: Restrict the use of removable media to prevent data exfiltration Ex5: Physically secure removable media containing unencrypted sensitive information, such as within locked offices or file cabinets | F63: Data Classification policy, showing when to apply encryption and other technical controls for data at rest. Representative technical/configuration evidence demonstrating implementation of applicable protection mechanisms. | G63: Security | K63: 3 | L63: =VLOOKUP(K63, 'Maturity Scale'!A:B,2,FALSE) -> Repeatable | M63: 3 | N63: =VLOOKUP(M63,'Maturity Scale'!A:B,2,FALSE) -> Repeatable | O63: =M63-K63 -> 0 | P63: Data is protected by individual teams
...

Sheet Evidence reference
A1: Governing evidence | B1: Policy / standard / approved criteria. | C1: What establishes the requirement?
A2: Implementation evidence | B2: Configuration / procedure / workflow / architecture. | C2: How has Northstar implemented it?
A3: Operating evidence | B3: Records / tickets / logs / reports / samples | C3: Show me that it actually happens.
A4: Effectiveness evidence | B4: esting / monitoring / metrics / review / remediation. | C4: How does Northstar know it works?

Sheet Maturity Scale
A1: 1 | B1: Partial
A2: 2 | B2: Risk Informed
A3: 3 | B3: Repeatable
A4: 4 | B4: Adaptive
A5: TBD | B5: TBD

Sheet Risk Matrix
A1: Likelihood | E1: Impact (CIA)
A2: Score | B2: Meaning | C2: Description | E2: Score | F2: Meaning
A3: 1 | B3: Rare | C3: Strong controls, limited exposure, no credible threat path | E3: 1 | F3: Insignificant
A4: 2 | B4: Unlikely | C4: Limited exposure and/or effective controls significantly reduce likelihood | E4: 2 | F4: Minor
A5: 3 | B5: Possible | C5: Credible threat path exists and some control weaknesses are present | E5: 3 | F5: Moderate
A6: 4 | B6: Likely | C6: Significant exposure/control weaknesses make exploitation reasonably plausible | E6: 4 | F6: Major
A7: 5 | B7: Almost Certain | C7: Direct exposure, exploitable weakness and/or strong threat activity make occurrence highly probable | E7: 5 | F7: Catastrophic
A9: Risk Score
A10: Score | B10: Level
A11: >20 | B11: P1: Critical
A12: 15-20 | B12: P2: High
A13: 10-14 | B13: P3: Medium
A14: <10 | B14: P4: Low

Sheet _EvidenceTypeLists
A1: Not Started
A2: Evidence Requested
A3: In Progress
A4: Partially Submitted
A5: Submitted
A6: Under Review
A7: Clarification Required
A8: Revision Requested
A9: Accepted
A10: Not Available
A11: Not Applicable
